// try n catch fun

try{
    let a=3/2
    console.log('a', a);
}    
catch(err){
    console.log("error",err);
}
